Workbook

Sheet Instructions
B2: How to use this workbook
B5: 1. Fill out the Visit Log
B6: • One row = one set visit. Start on row 3 (row 2 is a shaded EXAMPLE you can overwrite or delete).
B7: • The first 4 columns (Visit ID, Date, Production, Field Rep) stay frozen as you scroll right.
B8: • Columns are colour-coded by the 5 form sections, matching the paper X-4 form:
B9: Navy = ID • Blue = §1 Visit Details • Green = §2 Union Crew • Orange = §3 Non-Union • Purple = §4 Apparel • Red = §5 Production Notes
B10: • Cells with a dropdown arrow (Phase, Crew Day, Role, Dept, Size, and all Yes fields) – pick from the list.
B11: • Check-box items from the form (Areas Visited, Weather, Departments, Follow-ups) are 'Yes' columns – type/pick Yes when it applies, leave blank otherwise.
B12: • Dates: enter as real dates (e.g. 2026-07-15) so the monthly chart works.
B13: • Grey columns on the far right (# Union Crew, # Non-Union, # Depts, # Follow-ups) fill in automatically – don't type in them.
B15: 2. Watch the Dashboard
B16: • Every stat recalculates automatically the moment you add or edit a Visit Log row. No buttons, no macros.
... B24: Source form: IATSE Studio Mechanics Local 479 – Field Visit Report Form X-4 (2026). Every one of the form's 102 fields maps to a column here.

Sheet Visit Log
A1: Visit ID | B1: Date of Visit | C1: Production Title | D1: Field Representative | E1: L479 No. | F1: Date Production Notified | G1: Production Phase | H1: Arrival Time | I1: Departure Time | J1: Reason for Visit | K1: Crew Call | L1: Crew Day | M1: Area: Stage | N1: Area: Location | O1: Area: Mill | P1: Area: Lockup | Q1: Area: Other | R1: Visit Notes | S1: Wx: Sunny | T1: Wx: Cloudy | U1: Wx: Rain | V1: Wx: Snow | W1: Wx: Lightning | X1: Wx: Winds | Y1: Wx: Extreme Cold | Z1: Wx: Extreme Heat | AA1: Steward 1 Name | AB1: Steward 1 Status | AC1: Steward 1 Start Date | AD1: Steward 2 Name | AE1: Steward 2 Status | AF1: Steward 2 Start Date | AG1: Union Crew 1 Name | AH1: Union Crew 1 Role | AI1: Union Crew 1 Notes/Issues | AJ1: Union Crew 2 Name | AK1: Union Crew 2 Role | AL1: Union Crew 2 Notes/Issues | AM1: Union Crew 3 Name | AN1: Union Crew 3 Role | AO1: Union Crew 3 Notes/Issues | AP1: Union Crew 4 Name | AQ1: Union Crew 4 Role | AR1: Union Crew 4 Notes/Issues | AS1: Section 2 Notes | AT1: Dept: Art | AU1: Dept: Construction | AV1: Dept: Costumes | AW1: Dept: Craft Service | AX1: Dept: Electrical | AY1: Dept: Greens | AZ1: Dept: Grip | BA1: Dept: Locations | BB1: Dept: Medic | BC1: Dept: Paint | BD1: Dept: Plaster | BE1: Dept: Props | BF1: Dept: Set Dec | BG1: Dept: Set Teacher | BH1: Dept: Sound | BI1: Dept: SPFX | BJ1: Dept: Video | BK1: Non-Union 1 Name | BL1: Non-Union 1 Dept | BM1: Non-Union 2 Name | BN1: Non-Union 2 Dept | BO1: Non-Union 3 Name | BP1: Non-Union 3 Dept | BQ1: Non-Union 4 Name | BR1: Non-Union 4 Dept | BS1: Non-Union 5 Name | BT1: Non-Union 5 Dept | BU1: Non-Union 6 Name | BV1: Non-Union 6 Dept | BW1: Non-Union 7 Name | BX1: Non-Union 7 Dept | BY1: Non-Union 8 Name | BZ1: Non-Union 8 Dept | CA1: Section 3 Notes | CB1: Apparel 1 Name | CC1: Apparel 1 Phone | CD1: Apparel 1 Size | CE1: Apparel 2 Name | CF1: Apparel 2 Phone | CG1: Apparel 2 Size | CH1: Apparel 3 Name | CI1: Apparel 3 Phone | CJ1: Apparel 3 Size | CK1: Apparel 4 Name | CL1: Apparel 4 Phone | CM1: Apparel 4 Size | CN1: Apparel 5 Name | CO1: Apparel 5 Phone | CP1: Apparel 5 Size | CQ1: UPM/Producer 1 | CR1: UPM/Producer 2 | CS1: Production Coordinator | CT1: Follow-up: IATSE Project Info Sheet | CU1: Follow-up: Current Crewlist | CV1: Follow-up: 479 Roster Provided | CW1: Follow-up: Availability List Provided | CX1: Follow-up: Lunch Reporting Schedule | CY1: Section 5 Notes | CZ1: # Union Crew | DA1: # Non-Union | DB1: # Depts Visited | DC1: # Follow-ups Done
A2: 2026-001 | B2: 2026-07-15 | C2: Northern Lights (S2) | D2: J. Doe | E2: 250415-001 | F2: 2026-07-10 | G2: Shooting | H2: 9:30 AM | I2: 1:15 PM | J2: routine | K2: 7:00 AM | L2: Day | M2: Yes | N2: Yes | R2: All quiet. Stage 4 base camp. | T2: Yes | X2: Yes | AA2: A. Smith | AB2: On Production | AC2: 2026-06-01 | AG2: R. Lee | AH2: Key | AI2: None | AJ2: M. Ford | AK2: 2nd | AX2: Yes | AZ2: Yes | BF2: Yes | BK2: T. Nguyen | BL2: Construction | CB2: R. Lee | CC2: 555-0142 | CD2: Large | CQ2: C. Ramos | CS2: D. Park | CU2: Yes | CV2: Yes | CY2: Requested updated crew list; provided 479 roster. | CZ2: =IF(C2="","",COUNTA(AG2,AJ2,AM2,AP2)) | DA2: =IF(C2="","",COUNTA(BK2,BM2,BO2,BQ2,BS2,BU2,BW2,BY2)) | DB2: =IF(C2="","",COUNTIF(AT2:BJ2,"Yes")) | DC2: =IF(C2="","",COUNTIF(CT2:CX2,"Yes"))
CZ3: =IF(C3="","",COUNTA(AG3,AJ3,AM3,AP3)) | DA3: =IF(C3="","",COUNTA(BK3,BM3,BO3,BQ3,BS3,BU3,BW3,BY3)) | DB3: =IF(C3="","",COUNTIF(AT3:BJ3,"Yes")) | DC3: =IF(C3="","",COUNTIF(CT3:CX3,"Yes"))
CZ4: =IF(C4="","",COUNTA(AG4,AJ4,AM4,AP4)) | DA4: =IF(C4="","",COUNTA(BK4,BM4,BO4,BQ4,BS4,BU4,BW4,BY4)) | DB4: =IF(C4="","",COUNTIF(AT4:BJ4,"Yes")) | DC4: =IF(C4="","",COUNTIF(CT4:CX4,"Yes"))
CZ5: =IF(C5="","",COUNTA(AG5,AJ5,AM5,AP5)) | DA5: =IF(C5="","",COUNTA(BK5,BM5,BO5,BQ5,BS5,BU5,BW5,BY5)) | DB5: =IF(C5="","",COUNTIF(AT5:BJ5,"Yes")) | DC5: =IF(C5="","",COUNTIF(CT5:CX5,"Yes"))
CZ6: =IF(C6="","",COUNTA(AG6,AJ6,AM6,AP6)) | DA6: =IF(C6="","",COUNTA(BK6,BM6,BO6,BQ6,BS6,BU6,BW6,BY6)) | DB6: =IF(C6="","",COUNTIF(AT6:BJ6,"Yes")) | DC6: =IF(C6="","",COUNTIF(CT6:CX6,"Yes"))
CZ7: =IF(C7="","",COUNTA(AG7,AJ7,AM7,AP7)) | DA7: =IF(C7="","",COUNTA(BK7,BM7,BO7,BQ7,BS7,BU7,BW7,BY7)) | DB7: =IF(C7="","",COUNTIF(AT7:BJ7,"Yes")) | DC7: =IF(C7="","",COUNTIF(CT7:CX7,"Yes"))
CZ8: =IF(C8="","",COUNTA(AG8,AJ8,AM8,AP8)) | DA8: =IF(C8="","",COUNTA(BK8,BM8,BO8,BQ8,BS8,BU8,BW8,BY8)) | DB8: =IF(C8="","",COUNTIF(AT8:BJ8,"Yes")) | DC8: =IF(C8="","",COUNTIF(CT8:CX8,"Yes"))
CZ9: =IF(C9="","",COUNTA(AG9,AJ9,AM9,AP9)) | DA9: =IF(C9="","",COUNTA(BK9,BM9,BO9,BQ9,BS9,BU9,BW9,BY9)) | DB9: =IF(C9="","",COUNTIF(AT9:BJ9,"Yes")) | DC9: =IF(C9="","",COUNTIF(CT9:CX9,"Yes"))
CZ10: =IF(C10="","",COUNTA(AG10,AJ10,AM10,AP10)) | DA10: =IF(C10="","",COUNTA(BK10,BM10,BO10,BQ10,BS10,BU10,BW10,BY10)) | DB10: =IF(C10="","",COUNTIF(AT10:BJ10,"Yes")) | DC10: =IF(C10="","",COUNTIF(CT10:CX10,"Yes"))
CZ11: =IF(C11="","",COUNTA(AG11,AJ11,AM11,AP11)) | DA11: =IF(C11="","",COUNTA(BK11,BM11,BO11,BQ11,BS11,BU11,BW11,BY11)) | DB11: =IF(C11="","",COUNTIF(AT11:BJ11,"Yes")) | DC11: =IF(C11="","",COUNTIF(CT11:CX11,"Yes"))
CZ12: =IF(C12="","",COUNTA(AG12,AJ12,AM12,AP12)) | DA12: =IF(C12="","",COUNTA(BK12,BM12,BO12,BQ12,BS12,BU12,BW12,BY12)) | DB12: =IF(C12="","",COUNTIF(AT12:BJ12,"Yes")) | DC12: =IF(C12="","",COUNTIF(CT12:CX12,"Yes"))
CZ13: =IF(C13="","",COUNTA(AG13,AJ13,AM13,AP13)) | DA13: =IF(C13="","",COUNTA(BK13,BM13,BO13,BQ13,BS13,BU13,BW13,BY13)) | DB13: =IF(C13="","",COUNTIF(AT13:BJ13,"Yes")) | DC13: =IF(C13="","",COUNTIF(CT13:CX13,"Yes"))
CZ14: =IF(C14="","",COUNTA(AG14,AJ14,AM14,AP14)) | DA14: =IF(C14="","",COUNTA(BK14,BM14,BO14,BQ14,BS14,BU14,BW14,BY14)) | DB14: =IF(C14="","",COUNTIF(AT14:BJ14,"Yes")) | DC14: =IF(C14="","",COUNTIF(CT14:CX14,"Yes"))
... CZ300: =IF(C300="","",COUNTA(AG300,AJ300,AM300,AP300)) | DA300: =IF(C300="","",COUNTA(BK300,BM300,BO300,BQ300,BS300,BU300,BW300,BY300)) | DB300: =IF(C300="","",COUNTIF(AT300:BJ300,"Yes")) | DC300: =IF(C300="","",COUNTIF(CT300:CX300,"Yes"))

Sheet Dashboard
B2: IATSE Local 479 – Field Visit Report – Stats Dashboard
B3: Live stats – recalculates automatically as you add rows in the Visit Log.
B5: TOTALS | E5: BY PRODUCTION PHASE
B6: Total Visits Logged | C6: =COUNTA('Visit Log'!$A$2:$A$300) | E6: Prep | F6: =COUNTIF('Visit Log'!$G$2:$G$300,"Prep")
B7: Productions Tracked | C7: =SUMPRODUCT(('Visit Log'!$C$2:$C$300<>"")/COUNTIF('Visit Log'!$C$2:$C$300,'Visit Log'!$C$2:$C$300&"")) | E7: Shooting | F7: =COUNTIF('Visit Log'!$G$2:$G$300,"Shooting")
B8: Total Union Crew Logged | C8: =SUM('Visit Log'!$CZ$2:$CZ$300) | E8: Wrap | F8: =COUNTIF('Visit Log'!$G$2:$G$300,"Wrap")
B9: Total Non-Union Logged | C9: =SUM('Visit Log'!$DA$2:$DA$300)
B10: Follow-ups Completed | C10: =SUM('Visit Log'!$DC$2:$DC$300) | E10: BY CREW DAY
E11: Day | F11: =COUNTIF('Visit Log'!$L$2:$L$300,"Day")
B12: BY REASON FOR VISIT | E12: Night | F12: =COUNTIF('Visit Log'!$L$2:$L$300,"Night")
B13: Routine (contains 'routine') | C13: =COUNTIF('Visit Log'!$J$2:$J$300,"*routine*") | E13: Split | F13: =COUNTIF('Visit Log'!$L$2:$L$300,"Split")
B14: Issue (contains 'issue') | C14: =COUNTIF('Visit Log'!$J$2:$J$300,"*issue*")
B16: AREAS VISITED | E16: WEATHER CONDITIONS
B17: Stage | C17: =COUNTIF('Visit Log'!$M$2:$M$300,"Yes") | E17: Sunny | F17: =COUNTIF('Visit Log'!$S$2:$S$300,"Yes")
B18: Location | C18: =COUNTIF('Visit Log'!$N$2:$N$300,"Yes") | E18: Cloudy | F18: =COUNTIF('Visit Log'!$T$2:$T$300,"Yes")
B19: Mill | C19: =COUNTIF('Visit Log'!$O$2:$O$300,"Yes") | E19: Rain | F19: =COUNTIF('Visit Log'!$U$2:$U$300,"Yes")
B20: Lockup | C20: =COUNTIF('Visit Log'!$P$2:$P$300,"Yes") | E20: Snow | F20: =COUNTIF('Visit Log'!$V$2:$V$300,"Yes")
B21: Other | C21: =COUNTIF('Visit Log'!$Q$2:$Q$300,"Yes") | E21: Lightning | F21: =COUNTIF('Visit Log'!$W$2:$W$300,"Yes")
E22: Winds | F22: =COUNTIF('Visit Log'!$X$2:$X$300,"Yes")
E23: Extreme Cold | F23: =COUNTIF('Visit Log'!$Y$2:$Y$300,"Yes")
E24: Extreme Heat | F24: =COUNTIF('Visit Log'!$Z$2:$Z$300,"Yes")
B26: DEPARTMENTS VISITED (frequency) | E26: DEPARTMENTS (cont.)
B27: Art | C27: =COUNTIF('Visit Log'!$AT$2:$AT$300,"Yes") | E27: Paint | F27: =COUNTIF('Visit Log'!$BC$2:$BC$300,"Yes")
B28: Construction | C28: =COUNTIF('Visit Log'!$AU$2:$AU$300,"Yes") | E28: Plaster | F28: =COUNTIF('Visit Log'!$BD$2:$BD$300,"Yes")
B29: Costumes | C29: =COUNTIF('Visit Log'!$AV$2:$AV$300,"Yes") | E29: Props | F29: =COUNTIF('Visit Log'!$BE$2:$BE$300,"Yes")
B30: Craft Service | C30: =COUNTIF('Visit Log'!$AW$2:$AW$300,"Yes") | E30: Set Dec | F30: =COUNTIF('Visit Log'!$BF$2:$BF$300,"Yes")
B31: Electrical | C31: =COUNTIF('Visit Log'!$AX$2:$AX$300,"Yes") | E31: Set Teacher | F31: =COUNTIF('Visit Log'!$BG$2:$BG$300,"Yes")
B32: Greens | C32: =COUNTIF('Visit Log'!$AY$2:$AY$300,"Yes") | E32: Sound | F32: =COUNTIF('Visit Log'!$BH$2:$BH$300,"Yes")
B33: Grip | C33: =COUNTIF('Visit Log'!$AZ$2:$AZ$300,"Yes") | E33: SPFX | F33: =COUNTIF('Visit Log'!$BI$2:$BI$300,"Yes")
B34: Locations | C34: =COUNTIF('Visit Log'!$BA$2:$BA$300,"Yes") | E34: Video | F34: =COUNTIF('Visit Log'!$BJ$2:$BJ$300,"Yes")
B35: Medic | C35: =COUNTIF('Visit Log'!$BB$2:$BB$300,"Yes")
B36: FOLLOW-UP COMPLETION | E36: VISITS BY MONTH
B37: IATSE Project Info Sheet | C37: =COUNTIF('Visit Log'!$CT$2:$CT$300,"Yes") | E37: Year: | F37: 2026
B38: Current Crewlist | C38: =COUNTIF('Visit Log'!$CU$2:$CU$300,"Yes") | E38: Jan | F38: =COUNTIFS('Visit Log'!$B$2:$B$300,">="&DATE($F$37,1,1),'Visit Log'!$B$2:$B$300,"<"&DATE($F$37,2,1))
B39: 479 Roster Provided | C39: =COUNTIF('Visit Log'!$CV$2:$CV$300,"Yes") | E39: Feb | F39: =COUNTIFS('Visit Log'!$B$2:$B$300,">="&DATE($F$37,2,1),'Visit Log'!$B$2:$B$300,"<"&DATE($F$37,3,1))
B40: Availability List Provided | C40: =COUNTIF('Visit Log'!$CW$2:$CW$300,"Yes") | E40: Mar | F40: =COUNTIFS('Visit Log'!$B$2:$B$300,">="&DATE($F$37,3,1),'Visit Log'!$B$2:$B$300,"<"&DATE($F$37,4,1))
B41: Lunch Reporting Schedule | C41: =COUNTIF('Visit Log'!$CX$2:$CX$300,"Yes") | E41: Apr | F41: =COUNTIFS('Visit Log'!$B$2:$B$300,">="&DATE($F$37,4,1),'Visit Log'!$B$2:$B$300,"<"&DATE($F$37,5,1))
E42: May | F42: =COUNTIFS('Visit Log'!$B$2:$B$300,">="&DATE($F$37,5,1),'Visit Log'!$B$2:$B$300,"<"&DATE($F$37,6,1))
E43: Jun | F43: =COUNTIFS('Visit Log'!$B$2:$B$300,">="&DATE($F$37,6,1),'Visit Log'!$B$2:$B$300,"<"&DATE($F$37,7,1))
E44: Jul | F44: =COUNTIFS('Visit Log'!$B$2:$B$300,">="&DATE($F$37,7,1),'Visit Log'!$B$2:$B$300,"<"&DATE($F$37,8,1))
...
